<?xml version="1.0" ?>
<!-- =================================================================================== -->
<!-- |    This document was autogenerated by xacro from five_link_walker.xacro         | -->
<!-- |    EDITING THIS FILE BY HAND IS NOT RECOMMENDED                                 | -->
<!-- =================================================================================== -->
<robot name="five_link_walker" xmlns:xacro="http://ros.org/wiki/xacro">
  <link name="base">
    <inertial>
      <origin xyz="0 0 0.25"/>
      <mass value="15"/>
      <inertia ixx="0" ixy="0" ixz="0" iyy="0" iyz="0" izz="0"/>
    </inertial>
    <visual>
      <geometry>
        <sphere radius="0.05"/>
      </geometry>
      <material name="black">
        <color rgba="0 0 0 1"/>
      </material>
    </visual>
    <visual>
      <origin xyz="0 0 0.25"/>
      <geometry>
        <cylinder length="0.5" radius="0.025"/>
      </geometry>
      <material name="black">
        <color rgba="0 0 0 1"/>
      </material>
    </visual>
  </link>
  <link name="right_thigh">
    <inertial>
      <origin xyz="0 0 0.25"/>
      <mass value="5"/>
      <inertia ixx="0" ixy="0" ixz="0" iyy="0" iyz="0" izz="0"/>
    </inertial>
    <visual>
      <origin xyz="0 0 0.25"/>
      <geometry>
        <cylinder length="0.5" radius="0.025"/>
      </geometry>
      <material name="blue">
        <color rgba="0 0 1 1"/>
      </material>
    </visual>
  </link>
  <link name="left_thigh">
    <inertial>
      <origin xyz="0 0 0.25"/>
      <mass value="5"/>
      <inertia ixx="0" ixy="0" ixz="0" iyy="0" iyz="0" izz="0"/>
    </inertial>
    <visual>
      <origin xyz="0 0 0.25"/>
      <geometry>
        <cylinder length="0.5" radius="0.025"/>
      </geometry>
      <material name="red">
        <color rgba="1 0 0 1"/>
      </material>
    </visual>
  </link>
  <link name="right_shin">
    <inertial>
      <origin xyz="0 0 0.25"/>
      <mass value="5"/>
      <inertia ixx="0" ixy="0" ixz="0" iyy="0" iyz="0" izz="0"/>
    </inertial>
    <visual>
      <origin xyz="0 0 0.25"/>
      <geometry>
        <cylinder length="0.5" radius="0.025"/>
      </geometry>
      <material name="blue">
        <color rgba="1 0 0 1"/>
      </material>
    </visual>
  </link>
  <link name="left_shin">
    <inertial>
      <origin xyz="0 0 0.25"/>
      <mass value="5"/>
      <inertia ixx="0" ixy="0" ixz="0" iyy="0" iyz="0" izz="0"/>
    </inertial>
    <visual>
      <origin xyz="0 0 0.25"/>
      <geometry>
        <cylinder length="0.5" radius="0.025"/>
      </geometry>
      <material name="red">
        <color rgba="0 0 1 1"/>
      </material>
    </visual>
  </link>
  <joint name="q1_left" type="continuous">
    <origin xyz="0 0 0" rpy="0 0 0"/>
    <axis xyz="1 0 0"/>
    <parent link="base"/>
    <child link="left_thigh"/>
  </joint>
  <joint name="q1_right" type="continuous">
    <origin xyz="0 0 0"/>
    <axis xyz="1 0 0"/>
    <parent link="base"/>
    <child link="right_thigh"/>
  </joint>
  <joint name="q2_left" type="continuous">
    <origin xyz="0 0 0.5"/>
    <axis xyz="1 0 0"/>
    <parent link="left_thigh"/>
    <child link="left_shin"/>
  </joint>
  <joint name="q2_right" type="continuous">
    <origin xyz="0 0 0.5"/>
    <axis xyz="1 0 0"/>
    <parent link="right_thigh"/>
    <child link="right_shin"/>
  </joint>
</robot>
