<?xml version="1.0" ?>
<!-- =================================================================================== -->
<!-- |    This document was autogenerated by xacro from three_link_walker.xacro        | -->
<!-- |    EDITING THIS FILE BY HAND IS NOT RECOMMENDED                                 | -->
<!-- =================================================================================== -->
<robot name="three_link_walker" xmlns:xacro="http://ros.org/wiki/xacro">
  <link name="base">
    <inertial>
      <origin rpy="0 0 0" xyz="0 0 0"/>
      <mass value="15"/>
      <inertia ixx="0" ixy="0" ixz="0" iyy="0" iyz="0" izz="0"/>
    </inertial>
    <visual>
      <geometry>
        <sphere radius="0.05"/>
      </geometry>
      <material name="black">
        <color rgba="0 0 0 1"/>
      </material>
    </visual>
  </link>
  <!--<link name="torso">
    <inertial>
      <origin rpy="0 0 0" xyz="0 0 0.25"/>
      <mass value="10"/>
      <inertia ixx="0" ixy="0" ixz="0" iyy="0" iyz="0" izz="0"/>
    </inertial>
    <visual>
      <origin xyz="0 0 0.25"/>
      <geometry>
        <cylinder length="0.5" radius="0.025"/>
      </geometry>
      <material name="black">
        <color rgba="0 0 0 1"/>
      </material>
    </visual>
  </link>-->
  <link name="right_leg">
    <inertial>
      <origin rpy="0 0 0" xyz="0 0 0.5"/>
      <mass value="5"/>
      <inertia ixx="0" ixy="0" ixz="0" iyy="0" iyz="0" izz="0"/>
    </inertial>
    <visual>
      <origin xyz="0 0 0.5"/>
      <geometry>
        <cylinder length="1.0" radius="0.025"/>
      </geometry>
      <material name="blue">
        <color rgba="0 0 1 1"/>
      </material>
    </visual>
  </link>
  <link name="left_leg">
    <inertial>
      <origin rpy="0 0 0" xyz="0 0 0.5"/>
      <mass value="5"/>
      <inertia ixx="0" ixy="0" ixz="0" iyy="0" iyz="0" izz="0"/>
    </inertial>
    <visual>
      <origin xyz="0 0 0.5"/>
      <geometry>
        <cylinder length="1.0" radius="0.025"/>
      </geometry>
      <material name="red">
        <color rgba="1 0 0 1"/>
      </material>
    </visual>
  </link>
  <!--<joint name="qT" type="fixed">
    <parent link="base"/>
    <child link="torso"/>
  </joint>-->
  <joint name="q_right" type="continuous">
    <origin xyz="0 0 0"/>
    <axis xyz="1 0 0"/>
    <parent link="base"/>
    <child link="right_leg"/>
  </joint>
  <joint name="q_left" type="continuous">
    <origin xyz="0 0 0"/>
    <axis xyz="1 0 0"/>
    <parent link="base"/>
    <child link="left_leg"/>
  </joint>
</robot>
