<?xml version="1.0"?>

<robot name="three_link_walker" xmlns:xacro="http://ros.org/wiki/xacro">

  <xacro:property name="mT" value="10" />
  <xacro:property name="mH" value="15" />
  <xacro:property name="mL" value="5" />
  <xacro:property name="lT" value="0.5" />
  <xacro:property name="lL" value="1.0" />

  <!-- Links -->
  <xacro:torso cname="black" color="0 0 0 1" />
  <xacro:leg lr="right"  cname="blue" color="0 0 1 1" />
  <xacro:leg lr="left" cname="red" color="1 0 0 1" />

  <!-- Joints -->
  <xacro:q lr="right"/>
  <xacro:q lr="left"/>

 <xacro:macro name="torso" params="cname color">
    <link name="torso">
      <inertial>
        <origin xyz="0 0 ${(mT*lT/2)/(mT+mH)}" rpy="0 0 0" />
	        <mass value="${mT + mH}" />
        	<inertia ixx="0"  ixy="0"  ixz="0" iyy="0" iyz="0" izz="0" />
      </inertial>
      <visual>
      	<origin xyz="0 0 ${lT/2}" rpy="0 0 0" />
	      <geometry>
	        <cylinder radius="0.025" length="${lT}"/>
      	</geometry>
        <material name="${cname}">
          <color rgba="${color}" />
        </material>
      </visual>
    </link>
  </xacro:macro>

  <xacro:macro name="leg" params="lr cname color">
    <link name="${lr}_leg">
      <inertial>
        <origin xyz="0 0 ${lL/2}" rpy="0 0 0"/>
	        <mass value="${mL}" />
        	<inertia ixx="0"  ixy="0"  ixz="0" iyy="0" iyz="0" izz="0" />
      </inertial>
      <visual>
      	<origin xyz="0 0 ${lL/2}" rpy="0 0 0" />
	      <geometry>
	        <cylinder radius="0.025" length="${lL}"/>
      	</geometry>
        <material name="${cname}">
          <color rgba="${color}" />
        </material>
      </visual>
    </link>
  </xacro:macro>


  <xacro:macro name="q" params="lr">
   <joint name="q_${lr}" type="continuous">
      <origin xyz="0 0 0" rpy ="0 0 0"/>
      <axis xyz="0 1 0"/> 
      <parent link="torso" />
      <child link="${lr}_leg" /> 
    </joint>
  </xacro:macro>


</robot>





